Workbook

Sheet original data
A1: Date | B1: Description | C1: Debit | D1: Credit | E1: Sub-category | F1: Category | G1: Category Type
A2: 45300 | B2: Nextleap DAF | D2: ₹120,000.00 | E2: Nextleap DAF | F2: Salary | G2: Income
A3: 45300 | B3: Drink | C3: ₹120.00 | E3: Coffee | F3: Dining Out | G3: Expense
A4: 45301 | B4: Flat Expenses | C4: ₹21,600.00 | E4: Rent | F4: Living Expenses | G4: Expense
A5: 45301 | B5: EMI | C5: ₹3,600.00 | E5: Cash loan | F5: Transport | G5: Expense
A6: 45301 | B6: Drink | C6: ₹120.00 | E6: Coffee | F6: Dining Out | G6: Expense
A7: 45302 | B7: Drink | C7: ₹120.00 | E7: Coffee | F7: Dining Out | G7: Expense
A8: 45303 | B8: Drink | C8: ₹120.00 | E8: Coffee | F8: Dining Out | G8: Expense
A9: 45304 | B9: Drink | C9: ₹120.00 | E9: Coffee | F9: Dining Out | G9: Expense
A10: 45304 | B10: Green's | C10: ₹3,720.00 | E10: Groceries | F10: Living Expenses | G10: Expense
A11: 45307 | B11: Power source | C11: ₹1,200.00 | E11: Gas/Electrics | F11: Living Expenses | G11: Expense
A12: 45307 | B12: Drink | C12: ₹120.00 | E12: Coffee | F12: Dining Out | G12: Expense
A13: 45308 | B13: Drink | C13: ₹120.00 | E13: Coffee | F13: Dining Out | G13: Expense
A14: 45309 | B14: Fuel | C14: ₹1,848.00 | E14: Coffee | F14: Dining Out | G14: Expense
... A23: 45313 | B23: Ola | C23: ₹672.00 | E23: Taxi | F23: Transport | G23: Expense
A24: 45314 | B24: Onlne earning | D24: ₹108,000.00 | E24: YouTube | F24: Passive | G24: Income
A25: 45314 | B25: Drink | C25: ₹120.00 | E25: Coffee | F25: Dining Out | G25: Expense
A26: 45315 | B26: Drink | C26: ₹120.00 | E26: Coffee | F26: Dining Out | G26: Expense
A27: 45315 | B27: Onlne earning | D27: ₹108,000.00 | E27: Teachable | F27: Passive | G27: Income
A28: 45315 | B28: Phone | C28: ₹960.00 | E28: Phone | F28: Living Expenses | G28: Expense
A29: 45316 | B29: Family and Friends surprises | C29: ₹1,080.00 | E29: Gifts | F29: Discretionary | G29: Expense
A30: 45316 | B30: Online streaming | C30: ₹768.00 | E30: Entertainment | F30: Discretionary | G30: Expense
A31: 45316 | B31: Drink | C31: ₹120.00 | E31: Coffee | F31: Dining Out | G31: Expense
A32: 45317 | B32: Drink | C32: ₹120.00 | E32: Coffee | F32: Dining Out | G32: Expense
A33: 45318 | B33: Drink | C33: ₹120.00 | E33: Coffee | F33: Dining Out | G33: Expense
A34: 45318 | B34: Green's | C34: ₹4,080.00 | E34: Groceries | F34: Living Expenses | G34: Expense
A35: 45319 | B35: Office Lunch | C35: ₹888.00 | E35: Restaurant | F35: Dining Out | G35: Expense
A36: 45320 | B36: Evening snacks | C36: ₹288.00 | E36: Restaurant | F36: Dining Out | G36: Expense
A37: 45321 | B37: Orphanage | C37: ₹1,320.00 | E37: Donation | F37: Charity | G37: Expense
A38: 45321 | B38: Fuel | C38: ₹1,512.00 | E38: Fueling | F38: Transport | G38: Expense
A39: 45321 | B39: Drink | C39: ₹120.00 | E39: Coffee | F39: Dining Out | G39: Expense
... A48: 45327 | B48: Ola | C48: ₹552.00 | E48: Taxi | F48: Transport | G48: Expense
A49: 45328 | B49: Nextleap DAF | D49: ₹120,000.00 | E49: Data with Decision | F49: Salary | G49: Income
A50: 45328 | B50: Drink | C50: ₹120.00 | E50: Coffee | F50: Dining Out | G50: Expense
A51: 45329 | B51: Flat Expenses | C51: ₹21,600.00 | E51: Rent | F51: Living Expenses | G51: Expense
A52: 45329 | B52: EMI | C52: ₹3,600.00 | E52: Cash loan | F52: Transport | G52: Expense
A53: 45329 | B53: Drink | C53: ₹120.00 | E53: Coffee | F53: Dining Out | G53: Expense
A54: 45330 | B54: Drink | C54: ₹120.00 | E54: Coffee | F54: Dining Out | G54: Expense
A55: 45331 | B55: Drink | C55: ₹120.00 | E55: Coffee | F55: Dining Out | G55: Expense
A56: 45332 | B56: Drink | C56: ₹120.00 | E56: Coffee | F56: Dining Out | G56: Expense
...

Sheet cleaned data
A1: Date | B1: Description | C1: Debit | D1: Credit | E1: Sub-category | F1: Category | G1: Category Type | H1: Month | I1: Week
A2: 45300 | B2: Nextleap DAF | C2: =ROUND(IF(ISBLANK('original data'!C2),0,'original data'!C2),0) -> 0 | D2: =ROUND(IF(ISBLANK('original data'!D2),0,'original data'!D2),0) -> 120000 | E2: Nextleap DAF | F2: Salary | G2: Income | H2: =TEXT(A2,"MMMM") -> January | I2: =WEEKNUM(A2) -> 2
A3: 45300 | B3: Drink | C3: =ROUND(IF(ISBLANK('original data'!C3),0,'original data'!C3),0) -> 120 | D3: =ROUND(IF(ISBLANK('original data'!D3),0,'original data'!D3),0) -> 0 | E3: Coffee | F3: Dining Out | G3: Expense | H3: =TEXT(A3,"MMMM") -> January | I3: =WEEKNUM(A3) -> 2
A4: 45301 | B4: Flat Expenses | C4: =ROUND(IF(ISBLANK('original data'!C4),0,'original data'!C4),0) -> 21600 | D4: =ROUND(IF(ISBLANK('original data'!D4),0,'original data'!D4),0) -> 0 | E4: Rent | F4: Living Expenses | G4: Expense | H4: =TEXT(A4,"MMMM") -> January | I4: =WEEKNUM(A4) -> 2
A5: 45301 | B5: EMI | C5: =ROUND(IF(ISBLANK('original data'!C5),0,'original data'!C5),0) -> 3600 | D5: =ROUND(IF(ISBLANK('original data'!D5),0,'original data'!D5),0) -> 0 | E5: Cash loan | F5: Transport | G5: Expense | H5: =TEXT(A5,"MMMM") -> January | I5: =WEEKNUM(A5) -> 2
A6: 45301 | B6: Drink | C6: =ROUND(IF(ISBLANK('original data'!C6),0,'original data'!C6),0) -> 120 | D6: =ROUND(IF(ISBLANK('original data'!D6),0,'original data'!D6),0) -> 0 | E6: Coffee | F6: Dining Out | G6: Expense | H6: =TEXT(A6,"MMMM") -> January | I6: =WEEKNUM(A6) -> 2
A7: 45302 | B7: Drink | C7: =ROUND(IF(ISBLANK('original data'!C7),0,'original data'!C7),0) -> 120 | D7: =ROUND(IF(ISBLANK('original data'!D7),0,'original data'!D7),0) -> 0 | E7: Coffee | F7: Dining Out | G7: Expense | H7: =TEXT(A7,"MMMM") -> January | I7: =WEEKNUM(A7) -> 2
A8: 45303 | B8: Drink | C8: =ROUND(IF(ISBLANK('original data'!C8),0,'original data'!C8),0) -> 120 | D8: =ROUND(IF(ISBLANK('original data'!D8),0,'original data'!D8),0) -> 0 | E8: Coffee | F8: Dining Out | G8: Expense | H8: =TEXT(A8,"MMMM") -> January | I8: =WEEKNUM(A8) -> 2
A9: 45304 | B9: Drink | C9: =ROUND(IF(ISBLANK('original data'!C9),0,'original data'!C9),0) -> 120 | D9: =ROUND(IF(ISBLANK('original data'!D9),0,'original data'!D9),0) -> 0 | E9: Coffee | F9: Dining Out | G9: Expense | H9: =TEXT(A9,"MMMM") -> January | I9: =WEEKNUM(A9) -> 2
A10: 45304 | B10: Green's | C10: =ROUND(IF(ISBLANK('original data'!C10),0,'original data'!C10),0) -> 3720 | D10: =ROUND(IF(ISBLANK('original data'!D10),0,'original data'!D10),0) -> 0 | E10: Groceries | F10: Living Expenses | G10: Expense | H10: =TEXT(A10,"MMMM") -> January | I10: =WEEKNUM(A10) -> 2
A11: 45307 | B11: Power source | C11: =ROUND(IF(ISBLANK('original data'!C11),0,'original data'!C11),0) -> 1200 | D11: =ROUND(IF(ISBLANK('original data'!D11),0,'original data'!D11),0) -> 0 | E11: Gas/Electrics | F11: Living Expenses | G11: Expense | H11: =TEXT(A11,"MMMM") -> January | I11: =WEEKNUM(A11) -> 3
A12: 45307 | B12: Drink | C12: =ROUND(IF(ISBLANK('original data'!C12),0,'original data'!C12),0) -> 120 | D12: =ROUND(IF(ISBLANK('original data'!D12),0,'original data'!D12),0) -> 0 | E12: Coffee | F12: Dining Out | G12: Expense | H12: =TEXT(A12,"MMMM") -> January | I12: =WEEKNUM(A12) -> 3
A13: 45308 | B13: Drink | C13: =ROUND(IF(ISBLANK('original data'!C13),0,'original data'!C13),0) -> 120 | D13: =ROUND(IF(ISBLANK('original data'!D13),0,'original data'!D13),0) -> 0 | E13: Coffee | F13: Dining Out | G13: Expense | H13: =TEXT(A13,"MMMM") -> January | I13: =WEEKNUM(A13) -> 3
... A487: 45600 | B487: Foodary | C487: =ROUND(IF(ISBLANK('original data'!C487),0,'original data'!C487),0) -> 360 | D487: =ROUND(IF(ISBLANK('original data'!D487),0,'original data'!D487),0) -> 0 | E487: Restaurant | F487: Dining Out | G487: Expense | H487: =TEXT(A487,"MMMM") -> November | I487: =WEEKNUM(A487) -> 45

Sheet Pivot tables
A3: Expense Amount by Category | D3: Top 5 Expenses category | G3: Income Source | J3: Living Expense details | M3: Month wise Expanses,Income and Balance
A4: Row Labels | B4: Sum of Debit | D4: Row Labels | E4: Sum of Debit | G4: Row Labels | H4: Sum of Credit | J4: Sum of Debit | K4: Column Labels | M4: Row Labels | N4: Sum of Debit | O4: Sum of Credit | P4: Sum of Balance
A5: Charity | B5: 13200 | D5: Charity | E5: 13200 | G5: Passive | H5: 370560 | J5: Row Labels | K5: Living Expenses | M5: January | N5: 53496 | O5: 336000 | P5: 282504
A6: Dining Out | B6: 59372 | D6: Dining Out | E6: 59372 | G6: Salary | H6: 1200000 | J6: Flat Expenses | K6: 0.54878606 | M6: February | N6: 70648 | O6: 139200 | P6: 68552
A7: Discretionary | B7: 168664 | D7: Transport | E7: 84352 | G7: Grand Total | H7: 1570560 | J7: Green's | K7: 0.39355329 | M7: March | N7: 83007 | O7: 144000 | P7: 60993
A8: Living Expenses | B8: 393596 | D8: Discretionary | E8: 168664 | J8: Phone | K8: 0.024390492 | M8: April | N8: 62593 | O8: 176160 | P8: 113567
A9: Medical | B9: 5400 | D9: Living Expenses | E9: 393596 | J9: Power source | K9: 0.033270155 | M9: May | N9: 76271 | O9: 144000 | P9: 67729
A10: Transport | B10: 84352 | D10: Grand Total | E10: 719184 | J10: Grand Total | K10: 1 | M10: June | N10: 69372 | O10: 122400 | P10: 53028
A11: Grand Total | B11: 724584 | M11: July | N11: 72831 | O11: 124800 | P11: 51969
M12: August | N12: 72573 | O12: 139200 | P12: 66627
M13: September | N13: 71651 | O13: 122400 | P13: 50749
M14: October | N14: 74891 | O14: 122400 | P14: 47509
M15: November | N15: 17251 | O15: 0 | P15: -17251
M16: Grand Total | N16: 724584 | O16: 1570560 | P16: 845976
A17: Total Expenses | C17: Total Income | E17: Total Saving | G17: Percent of Expense and Savings | J17: Week wise Expanses and Income
A18: Sum of Debit | C18: Sum of Credit | E18: Sum of Savings | G18: Values | J18: Row Labels | K18: Sum of Debit | L18: Sum of Credit
A19: 724584 | C19: 1570560 | E19: 845976 | G19: Sum of Credit | H19: 1 | J19: 2 | K19: 29520 | L19: 120000
G20: Debit % | H20: 0.46135391 | J20: 3 | K20: 6888 | L20: 0
G21: Saving% | H21: 0.53864609 | J21: 4 | K21: 12840 | L21: 216000
J22: 5 | K22: 8496 | L22: 0
J23: 6 | K23: 41952 | L23: 120000
J24: 7 | K24: 6960 | L24: 0
J25: 8 | K25: 13050 | L25: 19200
J26: 9 | K26: 8588 | L26: 0
J27: 10 | K27: 39770 | L27: 120000
J28: 11 | K28: 7032 | L28: 0
J29: 12 | K29: 14986 | L29: 24000
J30: 13 | K30: 9768 | L30: 0
J31: 14 | K31: 37471 | L31: 120000
J32: 15 | K32: 5674 | L32: 0
J33: 16 | K33: 11461 | L33: 56160
... J62: 45 | K62: 12475 | L62: 0
J63: Grand Total | K63: 724584 | L63: 1570560

Sheet dashboard
W5: Insights & Suggestions
V7: 1) | W7: Top expense category - Living Expenses
V8: 2) | W8: Biggest spike in spending - In Month of March And 15th Week
V9: 3) | W9: Net monthly balance - Mostly Saving
V10: 4) | W10: Income dependency - On two sources
V11: 5) | W11: Actionable advice -
W12: Maintain current savings rate (54%); channel more into investments.
W13: If possible then low spend on living
W14: Explore another income sources to strengthen financial stability.
W15: Build an emergency fund of ~₹3.6L (6 months’ expenses).
W18: Conclusion -
W19: Your financial health looks strong — saving more than half of your income.The main improvement area is controlling discretionary spending and growing savings through smart investments.
